Workbook

Sheet README
A1: HIPAA Security Rule Gap Analysis & Risk Register
A2: Practice project · Fictional clinic scenario · 45 CFR Part 164 Subpart C
A4: PRACTICE PROJECT — FICTIONAL SCENARIO
A5: I invented Northwind Family Health as a scenario so I could work through a full HIPAA Security Rule gap analysis end to end. The clinic, its systems, and its problems are made up. The control set, the CFR citations, and the risk method are real: 45 CFR Part 164 Subpart C, NIST SP 800-66 Rev. 2, and NIST SP 800-30 Rev. 1.
A7: TAB GUIDE
A8: Asset Inventory | B8: 14 systems with ePHI classification, criticality, and owner. You cannot assess risk to data until you know where it lives.
A9: Control Gap Assessment | B9: All 65 standards and implementation specifications of the Security Rule, with a status, the evidence you would need to verify it, the gap in this scenario, and a NIST SP 800-53r5 mapping.
A10: Risk Register | B10: 15 risks scored Likelihood x Impact per NIST SP 800-30r1, with a treatment decision and residual risk.
A11: POA&M | B11: 20 remediation items with owner, rough cost, milestones, and target dates.
A13: RISK SCORING KEY — Risk Score = Likelihood (1-5) × Impact (1-5)
A14: Score | B14: Tier | C14: Remediation expectation
A15: 20 - 25 | B15: Critical | C15: Remediate within 30 days; executive visibility required
A16: 12 - 16 | B16: High | C16: Remediate within 90 days
A17: 6 - 10 | B17: Moderate | C17: Remediate within 180 days, or formally accept with documented rationale
A18: 1 - 5 | B18: Low | C18: Monitor; accept with annual review
A20: CONTROL ASSESSMENT SCALE
A21: Rating | B21: Definition | E21: Count | F21: % of 65
A22: Implemented | B22: Control operating effectively; evidence sampled and validated | E22: =COUNTIF('Control Gap Assessment'!$G$4:$G$68,$A22) -> 3 | F22: =E22/65 -> 0.046153846
A23: Partially Implemented | B23: Control exists but has scope, consistency, or documentation defects | E23: =COUNTIF('Control Gap Assessment'!$G$4:$G$68,$A23) -> 24 | F23: =E23/65 -> 0.36923077
A24: Not Implemented | B24: Control absent, or an addressable specification with no documented determination | E24: =COUNTIF('Control Gap Assessment'!$G$4:$G$68,$A24) -> 32 | F24: =E24/65 -> 0.49230769
A25: Alternative Measure | B25: Addressable specification not implemented as written; documented equivalent in place | E25: =COUNTIF('Control Gap Assessment'!$G$4:$G$68,$A25) -> 1 | F25: =E25/65 -> 0.015384615
A26: Not Applicable | B26: Documented rationale; specification does not apply to this entity | E26: =COUNTIF('Control Gap Assessment'!$G$4:$G$68,$A26) -> 5 | F26: =E26/65 -> 0.076923077
A27: TOTAL | E27: =SUM(E22:E26) -> 65 | F27: =SUM(F22:F26) -> 1
A29: RISK PROFILE — INHERENT vs RESIDUAL
A30: Tier | B30: Inherent (today) | C30: Residual (after full POA&M execution)
A31: Critical | B31: =COUNTIF('Risk Register'!$K$4:$K$18,$A31) -> 3 | C31: =COUNTIF('Risk Register'!$Q$4:$Q$18,$A31) -> 0
A32: High | B32: =COUNTIF('Risk Register'!$K$4:$K$18,$A32) -> 9 | C32: =COUNTIF('Risk Register'!$Q$4:$Q$18,$A32) -> 1
A33: Moderate | B33: =COUNTIF('Risk Register'!$K$4:$K$18,$A33) -> 3 | C33: =COUNTIF('Risk Register'!$Q$4:$Q$18,$A33) -> 9
A34: Low | B34: =COUNTIF('Risk Register'!$K$4:$K$18,$A34) -> 0 | C34: =COUNTIF('Risk Register'!$Q$4:$Q$18,$A34) -> 5
A37: HOW TO USE THIS WORKBOOK
A38: • | B38: Yellow-shaded cells are the only inputs. Everything else is a formula or written analysis.
A39: • | B39: On the Risk Register, Likelihood (H) and Impact (I) are inputs; Inherent Score, Tier, Residual Score and Residual Tier calculate automatically.
A40: • | B40: Changing a rating updates the tier colouring, the counts on this tab, and the risk profile above.
A41: • | B41: Example — R-01 is scored Likelihood 5 × Impact 5 = 25 (Critical). Set H4 to 2 and the row recalculates to 10 (Moderate).
A42: • | B42: Every gap cites the specific CFR provision it fails, so anyone reading it can check the reasoning against the regulation.
A45: AUTHORITIES
A46: 45 CFR Part 164 Subpart C — Security Standards for the Protection of Electronic Protected Health Information
A47: 45 CFR Part 164 Subpart D — Notification in the Case of Breach of Unsecured Protected Health Information
A48: NIST SP 800-66 Rev. 2 (February 2024) — Implementing the HIPAA Security Rule: A Cybersecurity Resource Guide
A49: NIST SP 800-30 Rev. 1 — Guide for Conducting Risk Assessments
...

Sheet Asset Inventory
A1: Asset and ePHI Inventory
A2: Systems that create, receive, maintain, or transmit ePHI in the scenario · 12 of 14 systems hold ePHI
A3: Asset ID | B3: System | C3: Type | D3: Contains ePHI | E3: Volume | F3: Criticality | G3: System Owner | H3: ePHI Description
A4: SYS-01 | B4: MedStream EHR | C4: Cloud SaaS (Business Associate) | D4: Yes - Primary repository | E4: 118,000 records | F4: Critical | G4: Clinical Director | H4: All clinical documentation, orders, results, demographics
A5: SYS-02 | B5: ClearPath RCM | C5: Cloud SaaS (Business Associate) | D5: Yes | E5: 42,000 records | F5: High | G5: Billing Manager | H5: Claims, remittance, insurance identifiers
A6: SYS-03 | B6: Microsoft 365 (Exchange / SharePoint / Teams) | C6: Cloud SaaS (Business Associate) | D6: Yes - Incidental | E6: Unbounded | F6: High | G6: IT Lead | H6: Referral correspondence, prior authorisations, attachments
A7: SYS-04 | B7: FS-01 file server | C7: On-premises Windows Server 2019 | D7: Yes | E7: ~380 GB scanned intake | F7: High | G7: IT Lead | H7: Scanned intake forms, consent documents, imaging landing directory
A8: SYS-05 | B8: Buckeye Imaging results feed | C8: Inbound SFTP (Business Associate) | D8: Yes | E8: ~900 studies/month | F8: Moderate | G8: Clinical Director | H8: Radiology reports and study metadata
A9: SYS-06 | B9: AfterHours Answering Service portal | C9: Cloud SaaS (Business Associate) | D9: Yes | E9: ~450 call notes/month | F9: Moderate | G9: Practice Administrator | H9: Patient name, callback number, presenting symptoms
A10: SYS-07 | B10: FaxLogic digital fax server | C10: On-premises appliance | D10: Yes | E10: ~61,000 stored images | F10: Moderate | G10: IT Lead | H10: Inbound and outbound faxes retained as unencrypted TIFF
A11: SYS-08 | B11: Backup infrastructure (Veeam / NAS / Wasabi) | C11: Hybrid on-premises and cloud | D11: Yes - Copies of all ePHI | E11: Full estate | F11: Critical | G11: IT Lead | H11: Nightly local backup, weekly offsite copy
A12: SYS-09 | B12: Active Directory / DNS / DHCP | C12: On-premises Windows Server 2019 | D12: No - Identity only | E12: 91 accounts | F12: Critical | G12: IT Lead | H12: Authentication and authorisation for the on-premises estate
A13: SYS-10 | B13: Workstations (62) | C13: Endpoint | D13: Yes - Cached and local | E13: Varies by device | F13: High | G13: IT Lead | H13: 56 of 62 encrypted; 6 unencrypted
A14: SYS-11 | B14: Laptops (14) | C14: Mobile endpoint | D14: Yes - Cached and local | E14: Varies by device | F14: High | G14: IT Lead | H14: 8 of 14 encrypted; 6 unencrypted; used for remote clinical work
... A17: SYS-14 | B17: Patient check-in kiosks (6) | C17: Endpoint | D17: Yes - Session | E17: Session only | F17: Moderate | G17: Practice Administrator | H17: Demographics and insurance capture at check-in

Sheet Control Gap Assessment
A1: HIPAA Security Rule Control Gap Assessment
A2: All 65 standards and implementation specifications · 45 CFR §§ 164.308, 164.310, 164.312, 164.314, 164.316
A3: Ref | B3: Safeguard | C3: CFR Citation | D3: Standard / Implementation Specification | E3: Type | F3: Control Objective | G3: Assessment Status | H3: Evidence You Would Need | I3: Gap / Observation | J3: Risk ID | K3: NIST SP 800-53r5
A4: A-01 | B4: Administrative | C4: 164.308(a)(1)(i) | D4: Security Management Process | E4: Standard | F4: Implement policies and procedures to prevent, detect, contain, and correct security violations. | G4: Not Implemented | H4: Inspect 2014 policy binder; interview Practice Administrator and IT Lead. | I4: No functioning security management process exists. The 2014 binder is an unfilled vendor template. There is no security committee, no defined cadence, and no evidence any of the four implementation specifications below have operated. | J4: R-02 | K4: PM-9, PL-1
A5: A-02 | B5: Administrative | C5: 164.308(a)(1)(ii)(A) | D5: Risk Analysis | E5: Required | F5: Conduct an accurate and thorough assessment of potential risks and vulnerabilities to the confidentiality, integrity, and availability of ePHI held by the entity. | G5: Not Implemented | H5: Request all prior risk analyses. Confirm with owner and Practice Administrator. | I5: No risk analysis has ever been conducted. This is the most frequently cited deficiency in OCR enforcement and is the foundational control on which every other risk decision depends. This engagement produces the first one. | J5: R-02 | K5: RA-3
A6: A-03 | B6: Administrative | C6: 164.308(a)(1)(ii)(B) | D6: Risk Management | E6: Required | F6: Implement security measures sufficient to reduce risks and vulnerabilities to a reasonable and appropriate level. | G6: Not Implemented | H6: Interview; no risk register, remediation plan, or acceptance documentation exists. | I6: With no risk analysis there is no risk management. Security spending has been reactive and undocumented. No risk has ever been formally accepted, transferred, or assigned an owner. | J6: R-02 | K6: RA-7, PM-4
A7: A-04 | B7: Administrative | C7: 164.308(a)(1)(ii)(C) | D7: Sanction Policy | E7: Required | F7: Apply appropriate sanctions against workforce members who fail to comply with security policies and procedures. | G7: Partially Implemented | H7: Review employee handbook (rev. 2023); interview HR Manager. | I7: The handbook contains a general disciplinary policy referencing 'violation of company policy' but does not reference HIPAA, information security, or ePHI, and does not establish a graduated sanction scale. No sanction has ever been applied for a security matter. Workforce members do not know a security sanction policy exists. | J7: R-13 | K7: PS-8
A8: A-05 | B8: Administrative | C8: 164.308(a)(1)(ii)(D) | D8: Information System Activity Review | E8: Required | F8: Implement procedures to regularly review records of information system activity, such as audit logs, access reports, and security incident tracking reports. | G8: Not Implemented | H8: Request 12 months of log review records; check whether the MedStream audit reports have ever been run. | I8: Logs are generated and retained but have never been reviewed. MedStream's break-the-glass and same-surname access reports are available in the vendor console and have never been opened. Veeam job failure alerts route to an unmonitored shared mailbox. | J8: R-11 | K8: AU-6
A9: A-06 | B9: Administrative | C9: 164.308(a)(2) | D9: Assigned Security Responsibility | E9: Standard (R) | F9: Identify the security official responsible for developing and implementing the required policies and procedures. | G9: Partially Implemented | H9: Review 2014 designation memo; interview the named individual. | I9: The Practice Administrator is named as Security Official in a 2014 memo, but holds the role as an undefined collateral duty with no allocated time, budget authority, or documented responsibilities. She was unaware of several core obligations of the role. The designation exists on paper only. | J9: R-02 | K9: PM-2
A10: A-07 | B10: Administrative | C10: 164.308(a)(3)(i) | D10: Workforce Security | E10: Standard | F10: Ensure all workforce members have appropriate access to ePHI and prevent those who should not have access from obtaining it. | G10: Partially Implemented | H10: Sample 20 of 91 accounts against role; interview HR and IT. | I10: Access is granted broadly by role at hire and rarely constrained thereafter. 20-account sample found 4 users with EHR access exceeding their job function, including a billing clerk with full clinical chart access. No least-privilege standard is defined. | J10: R-04 | K10: AC-2, PS-3
A11: A-08 | B11: Administrative | C11: 164.308(a)(3)(ii)(A) | D11: Authorization and/or Supervision | E11: Addressable | F11: Implement procedures for the authorization and/or supervision of workforce members who work with ePHI or in locations where it might be accessed. | G11: Partially Implemented | H11: Review 6 new-hire access request records; interview IT Lead. | I11: Access is authorized verbally by a supervisor and actioned by IT with no written record in 4 of 6 cases sampled. Clinical students and per-diem staff receive standing accounts with no supervision requirement documented. | J11: R-04 | K11: AC-2, PS-7
A12: A-09 | B12: Administrative | C12: 164.308(a)(3)(ii)(B) | D12: Workforce Clearance Procedure | E12: Addressable | F12: Implement procedures to determine that a workforce member's access to ePHI is appropriate. | G12: Partially Implemented | H12: Review HR onboarding checklist; sample 8 personnel files. | I12: Background checks are performed for clinical staff only. Administrative and IT staff, including the two individuals with domain administrator rights, received no clearance check. No periodic re-verification of access appropriateness occurs. | J12: R-04 | K12: PS-3, AC-2
A13: A-10 | B13: Administrative | C13: 164.308(a)(3)(ii)(C) | D13: Termination Procedures | E13: Addressable | F13: Implement procedures for terminating access to ePHI when employment or another arrangement ends. | G13: Not Implemented | H13: Reconcile the 2023-2025 separation list against Active Directory and MedStream user lists. | I13: No documented termination procedure for system access. Reconciliation found 7 enabled AD accounts and 4 active MedStream accounts for separated workforce members; one showed a successful login 11 days after the separation date. The HR exit checklist covers keys and badges but not system access. | J13: R-04 | K13: PS-4, AC-2(3)
A14: A-11 | B14: Administrative | C14: 164.308(a)(4)(i) | D14: Information Access Management | E14: Standard | F14: Implement policies and procedures for authorizing access to ePHI consistent with the Privacy Rule. | G14: Implemented | H14: Review all 9 MedStream role templates against job descriptions; sample 20 accounts against assigned role; interview Clinical Director. | I14: A documented role-based access model is configured in MedStream mapping 9 job functions to permission sets, and it is consistent with the Privacy Rule minimum necessary standard. Access is authorized against a defined role rather than granted ad hoc. The absence of a governing written policy is tracked under D-01, and the absence of periodic review under A-14; the access authorization model itself is sound. | K14: AC-1, AC-3
A15: A-12 | B15: Administrative | C15: 164.308(a)(4)(ii)(A) | D15: Isolating Health Care Clearinghouse Functions | E15: Required | F15: If the entity operates a clearinghouse as part of a larger organization, protect the clearinghouse's ePHI from the larger organization. | G15: Not Applicable | H15: Confirm entity structure with the owner; review the ClearPath service agreement. | I15: Northwind does not operate a health care clearinghouse. Clearinghouse functions are performed by ClearPath RCM as a business associate. Rationale documented; specification does not apply. | K15: N/A
A16: A-13 | B16: Administrative | C16: 164.308(a)(4)(ii)(B) | D16: Access Authorization | E16: Addressable | F16: Implement policies and procedures for granting access to ePHI through a workstation, transaction, program, process, or other mechanism. | G16: Partially Implemented | H16: Sample 6 access grants; review ticketing records. | I16: Grants occur but are not consistently documented. No standard access request form. No separation of duties between requester and approver — the IT Lead has, on at least two occasions, both requested and granted elevated access. | J16: R-04 | K16: AC-3, AC-6
A17: A-14 | B17: Administrative | C17: 164.308(a)(4)(ii)(C) | D17: Access Establishment and Modification | E17: Addressable | F17: Establish, document, review, and modify a user's right of access to a workstation, transaction, program, or process. | G17: Not Implemented | H17: Request access review records for the past 24 months. | I17: No periodic user access review has ever been conducted. Role changes and internal transfers result in accumulated access rather than modified access — 3 of 20 sampled users retained rights from a prior role. | J17: R-04 | K17: AC-2(1), AC-2(J)
A18: A-15 | B18: Administrative | C18: 164.308(a)(5)(i) | D18: Security Awareness and Training | E18: Standard | F18: Implement a security awareness and training program for all members of the workforce, including management. | G18: Not Implemented | H18: Request training completion records; review 2019 orientation deck; interview 11 workforce members. | I18: The only documented security training was a 2019 onboarding module. 34 workforce members hired since have received no security training. No annual refresher for anyone. 7 of 11 interviewees could not describe how to report a suspected security incident. | J18: R-13 | K18: AT-2
A19: A-16 | B19: Administrative | C19: 164.308(a)(5)(ii)(A) | D19: Security Reminders | E19: Addressable | F19: Provide periodic security updates to the workforce. | G19: Not Implemented | H19: Review staff communications and intranet postings for the past 24 months. | I19: No periodic security communications of any kind. No determination was ever documented as to whether reminders are reasonable and appropriate, which is itself a failure of the addressable-specification obligation under 164.306(d)(3). | J19: R-13 | K19: AT-2, AT-2(2)
A20: A-17 | B20: Administrative | C20: 164.308(a)(5)(ii)(B) | D20: Protection from Malicious Software | E20: Addressable | F20: Implement procedures for guarding against, detecting, and reporting malicious software. | G20: Partially Implemented | H20: Inspect endpoint configuration on 9 devices; review patch status of both servers. | I20: Microsoft Defender is present at default settings with no central management console, no alerting, and no verification of coverage. No EDR. FS-01 has not been patched since August 2025. No documented patch management cycle exists. | J20: R-05 | K20: SI-3, SI-2
A21: A-18 | B21: Administrative | C21: 164.308(a)(5)(ii)(C) | D21: Log-in Monitoring | E21: Addressable | F21: Implement procedures for monitoring log-in attempts and reporting discrepancies. | G21: Not Implemented | H21: Review available authentication logging; interview IT Lead. | I21: Failed login data is captured by MedStream and Entra ID but is never monitored, alerted on, or reported. No one would learn of a password-spray campaign against the practice. | J21: R-01 | K21: AC-7, AU-6
A22: A-19 | B22: Administrative | C22: 164.308(a)(5)(ii)(D) | D22: Password Management | E22: Addressable | F22: Implement procedures for creating, changing, and safeguarding passwords. | G22: Partially Implemented | H22: Review AD and MedStream password policy; observe workstation areas. | I22: Technical enforcement exists (8-character minimum, 90-day expiry) but is weaker than current NIST SP 800-63B guidance and is not supported by written procedure or training. Written passwords sit on notes at two Westerville workstations. | J22: R-01 | K22: IA-5
A23: A-20 | B23: Administrative | C23: 164.308(a)(6)(i) | D23: Security Incident Procedures | E23: Standard | F23: Implement policies and procedures to address security incidents. | G23: Not Implemented | H23: Request incident response plan and incident log. | I23: No incident response plan, no incident log, no defined roles, no severity criteria, and no reporting channel communicated to the workforce. Two potential incidents described in interviews (a lost phone with email access in 2024, a suspected phishing click in 2025) were never recorded or assessed for breach. | J23: R-13 | K23: IR-1, IR-4
A24: A-21 | B24: Administrative | C24: 164.308(a)(6)(ii) | D24: Response and Reporting | E24: Required | F24: Identify and respond to suspected or known security incidents; mitigate harmful effects to the extent practicable; and document incidents and their outcomes. | G24: Not Implemented | H24: Request 24 months of incident documentation. | I24: No documented incidents and no documentation capability. Critically, with no incident procedure there is no breach risk assessment process under 164.402, meaning Northwind cannot determine whether an incident is reportable within the 60-day deadline of 164.404. | J24: R-13 | K24: IR-4, IR-6, IR-8
A25: A-22 | B25: Administrative | C25: 164.308(a)(7)(i) | D25: Contingency Plan | E25: Standard | F25: Establish policies and procedures for responding to an emergency or other occurrence that damages systems containing ePHI. | G25: Partially Implemented | H25: Review the one-page continuity document; interview Clinical Director and IT Lead. | I25: A one-page vendor contact list exists and is described internally as the DR plan. It contains no roles, no decision authority, no recovery sequence, no downtime clinical procedures, and no communication plan. Clinical staff have no documented paper-based downtime workflow. | J25: R-07 | K25: CP-1, CP-2
A26: A-23 | B26: Administrative | C26: 164.308(a)(7)(ii)(A) | D26: Data Backup Plan | E26: Required | F26: Establish and implement procedures to create and maintain retrievable exact copies of ePHI. | G26: Partially Implemented | H26: Review Veeam job configuration and 12 months of job history; verify Wasabi bucket contents. | I26: Nightly backups run and mostly succeed, but the Wasabi offsite copy job failed silently 14 times in 12 months with no one reviewing the alerts. Backups are not immutable and the NAS is reachable from the production network, so a ransomware event could encrypt the backups with the source data. | J26: R-07 | K26: CP-9
A27: A-24 | B27: Administrative | C27: 164.308(a)(7)(ii)(B) | D27: Disaster Recovery Plan | E27: Required | F27: Establish procedures to restore any loss of data. | G27: Not Implemented | H27: Request restore procedures and test evidence. | I27: No documented restore procedure. No restore has ever been tested. Backup existence is not backup capability — an untested restore is an assumption, not a control. | J27: R-07 | K27: CP-10
... A51: T-06 | B51: Technical | C51: 164.312(b) | D51: Audit Controls | E51: Standard (R) | F51: Implement hardware, software, and/or procedural mechanisms that record and examine activity in information systems containing or using ePHI. | G51: Partially Implemented | H51: Verify logging configuration in MedStream, M365, and Windows; request review evidence. | I51: The recording half of this standard is largely satisfied — MedStream, M365, and Windows all generate audit records. The examining half is entirely absent. The standard requires mechanisms that record AND examine; recording alone does not satisfy it. M365 unified audit log is at default 90-day retention, below the six-year documentation expectation for records relied upon for compliance. | J51: R-11 | K51: AU-2, AU-6, AU-12
A52: T-07 | B52: Technical | C52: 164.312(c)(1) | D52: Integrity | E52: Standard | F52: Implement policies and procedures to protect ePHI from improper alteration or destruction. | G52: Implemented | H52: Try to alter a signed clinical note and a finalized order in MedStream. Review Volume Shadow Copy configuration on FS-01 and Wasabi object integrity settings. | I52: MedStream enforces an immutable clinical audit trail: signed notes cannot be altered, only amended with an attributed addendum, and the original is preserved. FS-01 has Volume Shadow Copy enabled with 14 days of retention, and Wasabi performs object-level integrity verification on the backup copies. Together these protect ePHI from improper alteration or destruction across all three primary stores. This is the strongest control area in the environment. | K52: SI-7
A53: T-08 | B53: Technical | C53: 164.312(c)(2) | D53: Mechanism to Authenticate ePHI | E53: Addressable | F53: Implement electronic mechanisms to corroborate that ePHI has not been altered or destroyed in an unauthorized manner. | G53: Alternative Measure | H53: Review MedStream vendor documentation and clinical audit trail sample. | I53: No independent checksum or file integrity monitoring is deployed. However, MedStream applies cryptographic integrity verification to the clinical record and Wasabi provides object-level integrity checking for backups, covering the two highest-value ePHI stores. This is accepted as an equivalent alternative measure for those systems; the FS-01 gap is tracked under T-07 and remains open. | J53: R-05 | K53: SI-7, AU-9
A54: T-09 | B54: Technical | C54: 164.312(d) | D54: Person or Entity Authentication | E54: Standard (R) | F54: Implement procedures to verify that a person or entity seeking access to ePHI is the one claimed. | G54: Not Implemented | H54: Attempt a remote login from an unmanaged device; check whether any second factor is required. | I54: Single-factor authentication only, for all users, on all systems, including remote access to the primary ePHI repository and including the two domain administrator accounts. Full patient records are reachable from an unmanaged external device with a password alone. This is the single highest-severity technical finding and the one most likely to be the proximate cause of a breach. | J54: R-01 | K54: IA-2, IA-2(1)
A55: T-10 | B55: Technical | C55: 164.312(e)(1) | D55: Transmission Security | E55: Standard | F55: Implement technical security measures to guard against unauthorized access to ePHI being transmitted over an electronic communications network. | G55: Partially Implemented | H55: Review M365 transport configuration; inspect SFTP and fax transmission paths. | I55: System-to-system paths are protected (TLS to MedStream and ClearPath, SFTP from Buckeye). Human-to-human paths are not: outbound email carrying ePHI relies on opportunistic TLS with no enforcement, and fax transmits over PSTN unprotected by nature with no compensating control or documented risk decision. | J55: R-12 | K55: SC-8
A56: T-11 | B56: Technical | C56: 164.312(e)(2)(i) | D56: Integrity Controls | E56: Addressable | F56: Implement security measures to ensure that electronically transmitted ePHI is not improperly modified without detection until disposed of. | G56: Implemented | H56: Inspect the negotiated cipher suite on each external interface; verify SFTP host key pinning and file checksum validation on the Buckeye feed. | I56: TLS 1.2 or higher with authenticated cipher suites is negotiated on every system-to-system interface, and the Buckeye SFTP feed performs host key verification and per-file checksum validation on receipt. Transmitted ePHI on these paths cannot be modified without detection. The separate exposure of unencrypted email and fax content is a confidentiality issue assessed under T-10 and T-12, not a transmission integrity failure. | K56: SC-8(1)
A57: T-12 | B57: Technical | C57: 164.312(e)(2)(ii) | D57: Encryption | E57: Addressable | F57: Implement a mechanism to encrypt ePHI whenever deemed appropriate. | G57: Not Implemented | H57: Send a test message to an external address and inspect the transport headers; review available M365 licensing. | I57: No email encryption mechanism is available to the workforce. Purview Message Encryption is included in the current M365 licence and is not enabled. Referral letters, prior authorisations, and after-hours call notes containing symptoms are routinely sent in plaintext. No determination was documented as to whether encryption is appropriate for these transmissions. | J57: R-12 | K57: SC-8, SC-13
A58: O-01 | B58: Organizational | C58: 164.314(a)(1) | D58: Business Associate Contracts or Other Arrangements | E58: Standard | F58: Ensure contracts or other arrangements with business associates meet the applicable requirements of this section. | G58: Partially Implemented | H58: Assess each BAA against the required elements of §164.314(a)(2)(i). | I58: Two of five agreements meet the requirements. One is absent, one is materially deficient, and one (MedStream) omits a breach notification timeline, leaving Northwind unable to guarantee its own 60-day notification obligation under §164.410. | J58: R-03 | K58: SA-9, CA-3
A59: O-02 | B59: Organizational | C59: 164.314(a)(2)(i) | D59: Business Associate Contracts | E59: Required | F59: The contract must provide that the business associate will comply with the Security Rule, ensure subcontractor compliance, and report security incidents including breaches of unsecured PHI. | G59: Partially Implemented | H59: Element-by-element review of each executed BAA. | I59: The ClearPath agreement lacks the subcontractor flow-down and incident reporting provisions added by the 2013 Omnibus Rule. The MedStream agreement includes incident reporting but specifies no deadline. The AfterHours relationship has no contract at all. | J59: R-03 | K59: SA-9, IR-6
A60: O-03 | B60: Organizational | C60: 164.314(a)(2)(ii) | D60: Other Arrangements | E60: Required | F60: Where both entities are governmental, satisfactory assurances may be met through alternative arrangements. | G60: Not Applicable | H60: Confirm the entity is a private LLC with no governmental business associate relationships. | I60: Northwind is a privately held LLC and none of its business associates are governmental entities. Rationale documented; specification does not apply. | K60: N/A
A61: O-04 | B61: Organizational | C61: 164.314(a)(2)(iii) | D61: Business Associate Contracts with Subcontractors | E61: Required | F61: A business associate must enter into a compliant contract with a subcontractor that creates, receives, maintains, or transmits ePHI on its behalf. | G61: Not Applicable | H61: Confirm entity status as a covered entity, not a business associate. | I61: This requirement is directed at business associates. Northwind is a covered entity and does not act as a business associate to any other entity. Flow-down to its BAs' subcontractors is assessed under O-02. | J61: R-03 | K61: N/A
A62: O-05 | B62: Organizational | C62: 164.314(b)(1) | D62: Requirements for Group Health Plans | E62: Standard | F62: A group health plan must ensure its plan documents require the plan sponsor to reasonably and appropriately safeguard ePHI. | G62: Not Applicable | H62: Confirm with the owner that Northwind sponsors a fully insured group health plan. | I62: Northwind sponsors a fully insured group health plan and does not create, receive, maintain, or transmit ePHI in its capacity as plan sponsor beyond enrollment and summary information. The exception at §164.314(b)(1) applies. Rationale documented. | K62: N/A
A63: O-06 | B63: Organizational | C63: 164.314(b)(2) | D63: Group Health Plan Implementation Specifications | E63: Required | F63: Plan documents must require the sponsor to implement safeguards, ensure agent compliance, report security incidents, and provide for adequate separation. | G63: Not Applicable | H63: Follows from O-05. | I63: Not applicable for the reason documented at O-05. Should Northwind move to a self-insured plan, this determination must be revisited immediately. | K63: N/A
...

Sheet Risk Register
A1: Risk Register
A2: Scored per NIST SP 800-30 Rev. 1 · Risk = Likelihood (1-5) × Impact (1-5) · Yellow cells are inputs; scores and tiers calculate
A3: Risk ID | B3: CFR Citation(s) | C3: Affected Asset(s) | D3: Threat Source | E3: Threat Event | F3: Vulnerability | G3: Existing Controls | H3: Likelihood | I3: Impact | J3: Inherent Score | K3: Inherent Tier | L3: Treatment | M3: Planned Control / Risk Response | N3: Resid. L | O3: Resid. I | P3: Residual Score | Q3: Residual Tier | R3: Risk Owner
A4: R-01 | B4: 164.312(d); 164.312(a)(1) | C4: SYS-01 MedStream EHR | D4: Adversarial — external criminal | E4: Credential stuffing or phishing yields provider EHR credentials; attacker logs in remotely and exfiltrates or ransoms patient records. | F4: Remote EHR access requires username and password only. No MFA, no conditional access, no IP restriction. Nothing blocks a login from an unmanaged personal device on a residential connection. | G4: Password complexity enforced by vendor (8 char min). Vendor-side account lockout after 10 failed attempts. | H4: 5 | I4: 5 | J4: =H4*I4 -> 25 | K4: =IF(J4>=20,"Critical",IF(J4>=12,"High",IF(J4>=6,"Moderate","Low"))) -> Critical | L4: Mitigate | M4: Enable MedStream native MFA for all 91 accounts; enforce for 100% of remote sessions. Add conditional access requiring compliant device for administrative roles. | N4: 2 | O4: 5 | P4: =N4*O4 -> 10 | Q4: =IF(P4>=20,"Critical",IF(P4>=12,"High",IF(P4>=6,"Moderate","Low"))) -> Moderate | R4: IT Lead
A5: R-02 | B5: 164.308(a)(1)(ii)(A); 164.308(a)(1)(ii)(B); 164.308(a)(8) | C5: Enterprise-wide | D5: Non-adversarial — organizational | E5: Undetected control failures accumulate; a breach occurs and OCR finds no risk analysis was ever conducted, escalating the penalty tier to willful neglect. | F5: No risk analysis has been performed since the practice was founded. No risk management process, no evaluation cycle, no security committee. The 2014 policy binder contains a vendor template with blanks unfilled. | G5: None. | H5: 5 | I5: 4 | J5: =H5*I5 -> 20 | K5: =IF(J5>=20,"Critical",IF(J5>=12,"High",IF(J5>=6,"Moderate","Low"))) -> Critical | L5: Mitigate | M5: Adopt this assessment as the baseline risk analysis. Establish an annual review cycle with documented management sign-off, and a standing quarterly security review meeting. | N5: 2 | O5: 4 | P5: =N5*O5 -> 8 | Q5: =IF(P5>=20,"Critical",IF(P5>=12,"High",IF(P5>=6,"Moderate","Low"))) -> Moderate | R5: Practice Administrator
A6: R-03 | B6: 164.308(b)(1); 164.314(a)(1); 164.314(a)(2)(i) | C6: SYS-02 ClearPath RCM; SYS-06 AfterHours portal | D6: Adversarial / Non-adversarial — third party | E6: A business associate suffers a breach or misuses ePHI; Northwind has no contractual right to notification, audit, or remediation, and is independently liable for the absent assurances. | F6: AfterHours Medical Answering has handled after-hours triage since 2019 with no BAA of any kind. The ClearPath BAA is dated 2016-03-02 and predates the 2013 Omnibus Rule; it contains no breach notification timeline and no subcontractor flow-down. | G6: MedStream, Microsoft, and Buckeye BAAs are current and adequate. | H6: 4 | I6: 4 | J6: =H6*I6 -> 16 | K6: =IF(J6>=20,"Critical",IF(J6>=12,"High",IF(J6>=6,"Moderate","Low"))) -> High | L6: Mitigate | M6: Execute a compliant BAA with AfterHours before 2026-05-15 or suspend the service. Re-paper ClearPath on current template. Establish an annual BAA review in the vendor onboarding checklist. | N6: 1 | O6: 4 | P6: =N6*O6 -> 4 | Q6: =IF(P6>=20,"Critical",IF(P6>=12,"High",IF(P6>=6,"Moderate","Low"))) -> Low | R6: Practice Administrator
A7: R-04 | B7: 164.308(a)(3)(ii)(C); 164.308(a)(4)(ii)(C) | C7: SYS-01, SYS-02, SYS-03, SYS-09 | D7: Adversarial — former workforce member | E7: A departed employee retains working credentials and accesses patient records for curiosity, personal gain, or retaliation. Insider access is the hardest breach category to detect and the most common in ambulatory settings. | F7: Termination is handled ad hoc by verbal request from HR to IT. Account review found 7 enabled Active Directory accounts and 4 active MedStream accounts belonging to workforce members separated between 2023 and 2025. One had logged in 11 days after separation. | G7: Badge/key collection is on the HR exit checklist. No system access step. | H7: 4 | I7: 4 | J7: =H7*I7 -> 16 | K7: =IF(J7>=20,"Critical",IF(J7>=12,"High",IF(J7>=6,"Moderate","Low"))) -> High | L7: Mitigate | M7: Add a mandatory IT access-revocation step to the HR separation checklist with a 4-hour SLA. Implement quarterly user access reviews signed by each system owner. Disable the 11 identified orphaned accounts immediately. | N7: 2 | O7: 4 | P7: =N7*O7 -> 8 | Q7: =IF(P7>=20,"Critical",IF(P7>=12,"High",IF(P7>=6,"Moderate","Low"))) -> Moderate | R7: IT Lead / HR Manager
A8: R-05 | B8: 164.308(a)(5)(ii)(B); 164.308(a)(1)(ii)(D); 164.308(a)(7)(i) | C8: SYS-04 FS-01; SYS-09; SYS-10 | D8: Adversarial — ransomware operator | E8: Ransomware encrypts the file server and propagates to workstations and the backup NAS, halting clinical operations across all three sites and triggering a presumed breach under §164.402. | F8: FS-01 has not received operating system patches since August 2025. No EDR — the estate runs Microsoft Defender with default settings and no central console. The backup NAS is reachable over SMB from the same broadcast domain with a shared local credential, so it is encryptable by the same intrusion. | G8: Perimeter FortiGate with IPS on default profile. Daily Veeam job to NAS with weekly Wasabi copy. | H8: 4 | I8: 5 | J8: =H8*I8 -> 20 | K8: =IF(J8>=20,"Critical",IF(J8>=12,"High",IF(J8>=6,"Moderate","Low"))) -> Critical | L8: Mitigate | M8: Deploy managed EDR to all 85 endpoints and both servers. Establish a monthly patch cycle with a documented emergency path. Segment the backup NAS onto an isolated VLAN with unique credentials and enable Wasabi object-lock immutability. | N8: 2 | O8: 5 | P8: =N8*O8 -> 10 | Q8: =IF(P8>=20,"Critical",IF(P8>=12,"High",IF(P8>=6,"Moderate","Low"))) -> Moderate | R8: IT Lead
A9: R-06 | B9: 164.308(a)(8); 164.308(a)(1)(ii)(A) | C9: Enterprise-wide | D9: Adversarial — external | E9: An exploitable vulnerability persists undetected in an internet-facing or internal system because no one is looking for it; discovery happens via exploitation rather than testing. | F9: No vulnerability scanning has ever been run. No penetration test. No external attack surface review. The periodic technical evaluation required by §164.308(a)(8) has never been performed in any form. | G9: None. | H9: 3 | I9: 4 | J9: =H9*I9 -> 12 | K9: =IF(J9>=20,"Critical",IF(J9>=12,"High",IF(J9>=6,"Moderate","Low"))) -> High | L9: Mitigate | M9: Procure quarterly authenticated vulnerability scanning. Commission an annual external penetration test. Note: the proposed Security Rule update would make both explicitly mandatory (6-month scan, annual pen test). | N9: 2 | O9: 4 | P9: =N9*O9 -> 8 | Q9: =IF(P9>=20,"Critical",IF(P9>=12,"High",IF(P9>=6,"Moderate","Low"))) -> Moderate | R9: IT Lead
A10: R-07 | B10: 164.308(a)(7)(ii)(A); 164.308(a)(7)(ii)(B); 164.308(a)(7)(ii)(D) | C10: SYS-08 Backup infrastructure | D10: Non-adversarial — technical failure | E10: A restore is attempted during a real outage and fails or takes days, extending a recoverable incident into a prolonged availability breach affecting patient care. | F10: Backups run nightly and report success, but no restore has ever been tested. No documented RTO or RPO. The disaster recovery plan consists of a one-page vendor contact list. Veeam job logs show 14 silent failures on the Wasabi copy job in the past 12 months that no one reviewed. | G10: Nightly Veeam job to NAS; weekly copy to Wasabi. Job success emails sent to a shared mailbox no one monitors. | H10: 3 | I10: 5 | J10: =H10*I10 -> 15 | K10: =IF(J10>=20,"Critical",IF(J10>=12,"High",IF(J10>=6,"Moderate","Low"))) -> High | L10: Mitigate | M10: Define RTO (8h) and RPO (24h) with clinical leadership. Perform and document a full restore test of FS-01 and a sample EHR export within 60 days, then semi-annually. Route job alerts to a monitored address. | N10: 1 | O10: 5 | P10: =N10*O10 -> 5 | Q10: =IF(P10>=20,"Critical",IF(P10>=12,"High",IF(P10>=6,"Moderate","Low"))) -> Low | R10: IT Lead
A11: R-08 | B11: 164.312(a)(2)(iv); 164.310(d)(1); 164.402 safe harbor | C11: SYS-10 Workstations; SYS-11 Laptops | D11: Non-adversarial — loss or theft | E11: An unencrypted laptop is lost or stolen. Because the device is not encrypted, the safe harbor for unsecured PHI does not apply and the incident is a presumed reportable breach with notification, HHS reporting, and possible media notice. | F11: 6 of 14 laptops and 6 of 62 workstations have no full-disk encryption. These predate the current IT Lead and were never enrolled in management tooling. No inventory of which devices are encrypted existed before this assessment. | G11: BitLocker enabled on 56 workstations and 8 laptops via a manual, undocumented process. | H11: 3 | I11: 4 | J11: =H11*I11 -> 12 | K11: =IF(J11>=20,"Critical",IF(J11>=12,"High",IF(J11>=6,"Moderate","Low"))) -> High | L11: Mitigate | M11: Enable BitLocker on all 12 remaining devices with escrowed recovery keys. Enroll the estate in Intune with an encryption compliance policy blocking non-compliant devices from M365. Add encryption verification to the device build checklist. | N11: 1 | O11: 4 | P11: =N11*O11 -> 4 | Q11: =IF(P11>=20,"Critical",IF(P11>=12,"High",IF(P11>=6,"Moderate","Low"))) -> Low | R11: IT Lead
A12: R-09 | B12: 164.312(a)(2)(iv); 164.316(b)(2)(i); 164.310(d)(2)(i) | C12: SYS-07 FaxLogic fax server | D12: Adversarial — internal or external | E12: The fax appliance is compromised or its disk is removed, exposing approximately 61,000 fax images containing patient names, diagnoses, and insurance identifiers in a single event. | F12: Sent and received faxes are retained as unencrypted TIFF images on local appliance disk with no retention limit, going back to 2021. The appliance's web console uses the vendor default administrator password. This system was undocumented and unknown to management before this assessment. | G12: Appliance sits on the internal network behind the firewall. | H12: 3 | I12: 4 | J12: =H12*I12 -> 12 | K12: =IF(J12>=20,"Critical",IF(J12>=12,"High",IF(J12>=6,"Moderate","Low"))) -> High | L12: Mitigate | M12: Change the default administrator credential immediately. Define and apply a 90-day retention policy with secure deletion. Enable appliance disk encryption or migrate to an encrypted cloud fax service with a BAA. | N12: 2 | O12: 3 | P12: =N12*O12 -> 6 | Q12: =IF(P12>=20,"Critical",IF(P12>=12,"High",IF(P12>=6,"Moderate","Low"))) -> Moderate | R12: IT Lead
A13: R-10 | B13: 164.310(a)(1); 164.310(a)(2)(ii); 164.310(a)(2)(iii) | C13: SYS-04, SYS-08, SYS-09, SYS-13 and all facilities | D13: Adversarial — unauthorized physical access | E13: An unauthorized person reaches server or network equipment, or an unattended workstation, and removes media or establishes persistent access. | F13: The Dublin IT closet housing FS-01 and the backup NAS is propped open during business hours for ventilation. Staff-door keypad codes at all three sites have not changed since 2019 and are known to former employees. No visitor log at any site. The Westerville cabinet key is kept in an unlocked front-desk drawer. | G13: Exterior doors locked outside operating hours. Alarm systems at all three sites. | H13: 3 | I13: 3 | J13: =H13*I13 -> 9 | K13: =IF(J13>=20,"Critical",IF(J13>=12,"High",IF(J13>=6,"Moderate","Low"))) -> Moderate | L13: Mitigate | M13: Install a ventilation solution and keep the Dublin closet locked. Rotate all keypad codes and establish a rotation on separation and semi-annually. Implement a visitor log and escort requirement for non-clinical areas. | N13: 2 | O13: 3 | P13: =N13*O13 -> 6 | Q13: =IF(P13>=20,"Critical",IF(P13>=12,"High",IF(P13>=6,"Moderate","Low"))) -> Moderate | R13: Practice Administrator
A14: R-11 | B14: 164.308(a)(1)(ii)(D); 164.312(b) | C14: SYS-01, SYS-02, SYS-03, SYS-04 | D14: Adversarial — insider snooping | E14: A workforce member browses the records of a neighbour, family member, colleague, or local public figure. Without log review this is invisible; it is also the most common HIPAA complaint OCR receives about practices of this size. | F14: MedStream generates access audit logs and has a break-the-glass report available, but no one at Northwind has ever opened it. No log review procedure, no defined review frequency, no record of any review. Windows and M365 audit logs are retained at default and never examined. | G14: Logging is enabled and retained by vendors. No review occurs. | H14: 4 | I14: 3 | J14: =H14*I14 -> 12 | K14: =IF(J14>=20,"Critical",IF(J14>=12,"High",IF(J14>=6,"Moderate","Low"))) -> High | L14: Mitigate | M14: Define a monthly log review procedure: same-surname access report, VIP/employee-record access report, and after-hours access report from MedStream, reviewed and signed by the Security Official. Enable M365 unified audit log retention. | N14: 2 | O14: 3 | P14: =N14*O14 -> 6 | Q14: =IF(P14>=20,"Critical",IF(P14>=12,"High",IF(P14>=6,"Moderate","Low"))) -> Moderate | R14: Practice Administrator
A15: R-12 | B15: 164.312(e)(1); 164.312(e)(2)(ii) | C15: SYS-03 Microsoft 365; SYS-06 AfterHours portal | D15: Non-adversarial — interception / misdirection | E15: ePHI sent by email traverses the internet unencrypted or is misaddressed, disclosing patient information to an unintended recipient. | F15: Outbound email uses opportunistic TLS with no enforcement and no encryption policy. Referral letters, prior-authorisation documents, and after-hours call notes containing symptoms and contact details are routinely sent in the plaintext message body. No patient portal is in use for most communications. No data loss prevention rules exist. | G15: TLS is used when the receiving server supports it. Microsoft BAA in place. | H15: 4 | I15: 3 | J15: =H15*I15 -> 12 | K15: =IF(J15>=20,"Critical",IF(J15>=12,"High",IF(J15>=6,"Moderate","Low"))) -> High | L15: Mitigate | M15: Enable Microsoft Purview Message Encryption with a transport rule triggering on PHI-indicative content. Configure DLP policies for the US HIPAA template in audit mode, then enforce. Require the AfterHours portal to deliver via secure link rather than email body. | N15: 2 | O15: 3 | P15: =N15*O15 -> 6 | Q15: =IF(P15>=20,"Critical",IF(P15>=12,"High",IF(P15>=6,"Moderate","Low"))) -> Moderate | R15: IT Lead
... A18: R-15 | B18: 164.312(d); 164.312(e)(1); 164.308(a)(4)(ii)(C) | C18: SYS-05 Buckeye Imaging SFTP feed | D18: Adversarial — credential compromise | E18: The SFTP key pair used for the imaging results feed is compromised or held by a departed vendor employee, allowing interception or injection of radiology results. | F18: The SFTP key pair was generated at onboarding in September 2022 and has never been rotated. No inventory of who holds the private key on the Buckeye side. Inbound files land in an unencrypted directory on FS-01. | G18: SFTP provides encryption in transit. Buckeye holds a current BAA and SOC 2 Type II. | H18: 2 | I18: 3 | J18: =H18*I18 -> 6 | K18: =IF(J18>=20,"Critical",IF(J18>=12,"High",IF(J18>=6,"Moderate","Low"))) -> Moderate | L18: Mitigate | M18: Rotate the key pair and establish annual rotation. Request Buckeye's key custody documentation. Move the landing directory to an encrypted volume with restricted ACLs. | N18: 1 | O18: 3 | P18: =N18*O18 -> 3 | Q18: =IF(P18>=20,"Critical",IF(P18>=12,"High",IF(P18>=6,"Moderate","Low"))) -> Low | R18: IT Lead
A20: Note | B20: Likelihood and Impact scales are defined in scenario.md. Impact is the highest of three axes: patient safety, regulatory exposure, and operations. Threat sources come from NIST SP 800-30r1 Appendix D, narrowed to the ones that actually show up in HHS breach reports for small medical practices.

Sheet POA&M
A1: Plan of Action and Milestones
A2: Remediation tracker · 20 items · Statuses show a plan part-way through execution
A3: POA&M ID | B3: Risk ID | C3: Priority | D3: Remediation Action | E3: Owner | F3: Resources / Estimated Cost | G3: Start Date | H3: Target Date | I3: Status | J3: % Complete | K3: Milestones | L3: Days to Target
A4: PM-01 | B4: R-01 | C4: 1 - Immediate | D4: Enable MedStream native MFA for all 91 user accounts; enforce on 100% of remote sessions; require compliant device via conditional access for the 4 administrative roles. | E4: IT Lead | F4: $0 licence (included) + ~24h internal effort | G4: 2026-04-06 | H4: 2026-05-04 | I4: In Progress | J4: 0.4 | K4: Pilot with 8 providers (04-13) | Full rollout (04-27) | Enforcement mode + exception review (05-04) | L4: =DATEVALUE(H4)-DATEVALUE("2026-04-03") -> 31
A5: PM-02 | B5: R-02 | C5: 1 - Immediate | D5: Formally adopt this risk analysis as the baseline. Establish a documented annual review cycle and a standing quarterly security review meeting with owner sign-off. | E5: Practice Administrator | F5: ~16h internal effort per year | G5: 2026-04-06 | H5: 2026-04-30 | I5: In Progress | J5: 0.6 | K5: Management review meeting (04-15) | Signed adoption memo (04-22) | Q2 meeting scheduled (04-30) | L5: =DATEVALUE(H5)-DATEVALUE("2026-04-03") -> 27
A6: PM-03 | B6: R-05 | C6: 1 - Immediate | D6: Deploy managed EDR to 85 endpoints and 2 servers. Establish a monthly patch cycle with a documented emergency path. Bring FS-01 current. | E6: IT Lead | F6: ~$4,300/yr licensing + $2,000 deployment | G6: 2026-04-13 | H6: 2026-06-15 | I6: In Progress | J6: 0.25 | K6: Vendor selected (04-20) | FS-01 patched to current (04-24) | EDR on all servers (05-11) | Full endpoint coverage (06-15) | L6: =DATEVALUE(H6)-DATEVALUE("2026-04-03") -> 73
A7: PM-04 | B7: R-05 | C7: 2 - High | D7: Segment the backup NAS onto an isolated VLAN with a unique credential; enable Wasabi object-lock immutability with a 35-day retention lock. | E7: IT Lead | F7: $0 (existing licensing) + ~12h | G7: 2026-05-04 | H7: 2026-06-30 | I7: Not Started | J7: 0 | K7: VLAN designed (05-11) | NAS migrated and credential rotated (06-08) | Immutability enabled and verified (06-30) | L7: =DATEVALUE(H7)-DATEVALUE("2026-04-03") -> 88
A8: PM-05 | B8: R-03 | C8: 1 - Immediate | D8: Execute a compliant BAA with AfterHours Medical Answering or suspend the service. Re-paper the ClearPath BAA on the current template. Obtain a breach notification timeline addendum from MedStream. | E8: Practice Administrator | F8: ~$1,800 legal review | G8: 2026-04-06 | H8: 2026-05-15 | I8: In Progress | J8: 0.33 | K8: Template obtained from counsel (04-17) | AfterHours executed (05-01) | ClearPath executed (05-15) | L8: =DATEVALUE(H8)-DATEVALUE("2026-04-03") -> 42
A9: PM-06 | B9: R-04 | C9: 1 - Immediate | D9: Disable the 11 identified orphaned accounts. Add a mandatory IT access-revocation step to the HR separation checklist with a 4-hour SLA. | E9: IT Lead / HR Manager | F9: ~8h internal effort | G9: 2026-04-06 | H9: 2026-04-24 | I9: Complete | J9: 1 | K9: 11 accounts disabled (04-08) | Revised checklist approved (04-17) | HR trained on new step (04-24) | L9: =DATEVALUE(H9)-DATEVALUE("2026-04-03") -> 21
A10: PM-07 | B10: R-04 | C10: 2 - High | D10: Implement quarterly user access reviews across MedStream, ClearPath, M365, and AD, with attestation signed by each system owner. Remediate the 4 sampled over-provisioned accounts. | E10: IT Lead | F10: ~10h per quarter | G10: 2026-05-04 | H10: 2026-07-31 | I10: Not Started | J10: 0 | K10: Review procedure documented (05-22) | Extract tooling built (06-15) | First full review completed and signed (07-31) | L10: =DATEVALUE(H10)-DATEVALUE("2026-04-03") -> 119
A11: PM-08 | B11: R-13 | C11: 2 - High | D11: Deploy an annual role-based security awareness program with tracked completion for 100% of the workforce; begin monthly phishing simulations; issue quarterly security reminders. | E11: Practice Administrator / HR | F11: ~$2,400/yr platform | G11: 2026-04-20 | H11: 2026-07-15 | I11: In Progress | J11: 0.15 | K11: Platform procured (05-01) | Baseline phishing simulation (05-15) | 100% training completion (07-01) | Reminder calendar published (07-15) | L11: =DATEVALUE(H11)-DATEVALUE("2026-04-03") -> 103
A12: PM-09 | B12: R-07 | C12: 2 - High | D12: Define RTO (8h) and RPO (24h) with clinical leadership. Perform and document a full restore test of FS-01 and a sample EHR export. Route backup job alerts to a monitored address. | E12: IT Lead | F12: ~20h internal effort | G12: 2026-04-20 | H12: 2026-06-19 | I12: In Progress | J12: 0.2 | K12: RTO/RPO agreed with clinical leadership (05-08) | Alerting rerouted (04-30) | First documented restore test (06-19) | L12: =DATEVALUE(H12)-DATEVALUE("2026-04-03") -> 77
A13: PM-10 | B13: R-08 | C13: 2 - High | D13: Enable BitLocker with escrowed recovery keys on the 12 unencrypted devices. Enrol the estate in Intune with an encryption compliance policy blocking non-compliant devices from M365. | E13: IT Lead | F13: $0 (existing licensing) + ~30h | G13: 2026-04-27 | H13: 2026-07-06 | I13: Not Started | J13: 0 | K13: Recovery key escrow configured (05-11) | 12 devices encrypted (06-05) | Intune compliance policy enforced (07-06) | L13: =DATEVALUE(H13)-DATEVALUE("2026-04-03") -> 94
A14: PM-11 | B14: R-11 | C14: 2 - High | D14: Establish a documented monthly log review: same-surname access, employee/VIP record access, and after-hours access reports from MedStream, reviewed and signed by the Security Official. Extend M365 audit retention. | E14: Practice Administrator | F14: ~4h per month | G14: 2026-05-04 | H14: 2026-06-30 | I14: Not Started | J14: 0 | K14: Report set defined with MedStream (05-18) | Procedure documented (06-05) | First signed monthly review (06-30) | L14: =DATEVALUE(H14)-DATEVALUE("2026-04-03") -> 88
A15: PM-12 | B15: R-12 | C15: 3 - Moderate | D15: Enable Purview Message Encryption with a transport rule on PHI-indicative content. Deploy the US HIPAA DLP template in audit mode, then enforce. Require AfterHours to deliver via secure link. | E15: IT Lead | F15: $0 (included in current licence) + ~16h | G15: 2026-06-01 | H15: 2026-08-31 | I15: Not Started | J15: 0 | K15: Encryption rule piloted (06-22) | DLP in audit mode (07-20) | DLP enforced + staff guidance issued (08-31) | L15: =DATEVALUE(H15)-DATEVALUE("2026-04-03") -> 150
... A23: PM-20 | B23: R-02 | C23: 2 - High | D23: Formally adopt the asset and ePHI inventory produced by this engagement; assign custodians; establish an annual review and a change-triggered update process. | E23: IT Lead / Practice Administrator | F23: ~8h initial + 4h annually | G23: 2026-04-20 | H23: 2026-06-15 | I23: In Progress | J23: 0.7 | K23: Inventory validated with system owners (05-08) | Custodians assigned (05-22) | Review cadence documented (06-15) | L23: =DATEVALUE(H23)-DATEVALUE("2026-04-03") -> 73
A25: Summary | D25: ="Items: "&COUNTA(A4:A23)&" | Complete: "&COUNTIF(I4:I23,"Complete")&" | In Progress: "&COUNTIF(I4:I23,"In Progress")&" | Not Started: "&COUNTIF(I4:I23,"Not Started") -> Items: 20 | Complete: 1 | In Progress: 10 | Not Started: 9 | J25: =AVERAGE(J4:J23) -> 0.2465 | K25: Average completion across all POA&M items
